Workbook

Sheet How to use
A1: Earth Movers International - Redirect Map for the new website
A3: Source: Google Search Console, earthmoversint.com, 29 May - 28 Aug 2026 (74 URLs)
A5: WHAT TO DO
A6: 1. | B6: Open the "Redirect Map" tab.
A7: 2. | B7: Work down from Tier A. Fill in column H (New URL) for every row.
A8: 3. | B8: Column H is the only column you edit. It is shaded yellow.
A9: 4. | B9: Give the completed column to whoever sets up the 301 redirects.
A11: TIERS
A12: A | B12: Must preserve. Keep the URL identical on the new site if at all possible. | C12: 14 URLs / 369 clicks
A13: B | B13: Preserve. Keep the URL, or 301 to the closest equivalent. | C13: 32 URLs / 150 clicks
A14: C | B14: Redirect. Low traffic but real equity. 301 to the closest new page. | C14: 15 URLs / 21 clicks
A15: D | B15: Low value. 301 to a parent page, or allow a 404. | C15: 13 URLs / 0 clicks
A17: RULES
B18: Use 301 (permanent), never 302.
B19: Map page to page. Never send everything to the homepage - Google treats that as a soft 404 and passes no value.
B20: If there is genuinely no equivalent page, a 404 is better than a bad redirect.
B21: Avoid chains. Old URL should point straight to the final destination, not via another redirect.
B22: Keep redirects live permanently while you own the domain.
A24: EXAMPLE ROW
A25: Old URL | B25: /cut-and-fill-services-dubai/
A26: New URL (what you type in column H) | B26: /services/earthworks/cut-and-fill/

Sheet Redirect Map
A1: Tier | B1: Old URL | C1: Clicks | D1: Impressions | E1: CTR | F1: Avg position | G1: Recommended action | H1: NEW URL (fill in) | I1: Notes
A2: A | B2: / | C2: 154 | D2: 4480 | E2: 0.0344 | F2: 35.1 | G2: Keep URL identical | H2: / | I2: URL PRESERVED as-is. Homepage. 154 clicks. Never change.
A3: A | B3: /backfilling/ | C3: 30 | D3: 1451 | E3: 0.0207 | F3: 9.7 | G3: Keep URL identical | H3: /services/earth-works/back-filling | I3: Best service page: pos 9.7, CTR 2.07%. Keep URL exactly.
A4: A | B4: /road-construction-process/ | C4: 20 | D4: 5002 | E4: 0.004 | F4: 11.4 | G4: Keep URL identical | H4: /road-construction-process | I4: URL PRESERVED as-is. Biggest impression source (5,002) + 2,009 AI Overview impressions. Keep, add CTAs to service pages.
A5: A | B5: /asphalt-contractors-dubai/ | C5: 20 | D5: 4013 | E5: 0.005 | F5: 13.3 | G5: Keep URL identical | H5: /services/road-works/asphalt-works | I5: CORE PRODUCT. Duplicate exists on asphaltcontractordubai.ae - consolidate here.
A6: A | B6: /road-construction-abu-dhabi/ | C6: 20 | D6: 1731 | E6: 0.0116 | F6: 30 | G6: Keep URL identical | H6: /services/road-works/abu-dhabi | I6: Location page working. Keep.
A7: A | B7: /rta-approved-entry-exit-works/ | C7: 19 | D7: 1531 | E7: 0.0124 | F7: 7.2 | G7: Keep URL identical | H7: /services/utilities/rta-approved-entry-exit-works | I7: Best commercial position on site (7.18). RTA approval is your differentiator.
A8: A | B8: /traffic-management-abu-dhabi/ | C8: 17 | D8: 847 | E8: 0.0201 | F8: 21 | G8: Keep URL identical | H8: /services/traffic-management/abu-dhabi | I8: NEW PAGE to be built. CTR 2.01%. Keep.
A9: A | B9: /material-shifting-services-dubai/ | C9: 15 | D9: 2603 | E9: 0.0058 | F9: 10.1 | G9: Keep URL identical | H9: /services/supply/material-shifting | I9: NEW PAGE to be built. Pos 10.1. Note /material-shifting-in-dubai/ is a near-duplicate - consolidate.
A10: A | B10: /stone-supply-dubai/ | C10: 15 | D10: 1496 | E10: 0.01 | F10: 31.8 | G10: Keep URL identical | H10: /services/supply/stone-supply | I10: NEW PAGE to be built. Keep. Pairs with aggregate/sand supply pages.
A11: A | B11: /road-base-supply-dubai/ | C11: 13 | D11: 1606 | E11: 0.0081 | F11: 19.4 | G11: Keep URL identical | H11: /services/supply/road-base-supply | I11: NEW PAGE to be built. CORE PRODUCT. 297 impressions for "road base supplier in dubai". Keep URL, expand content.
A12: A | B12: /contact/ | C12: 12 | D12: 1098 | E12: 0.0109 | F12: 22.9 | G12: Keep URL identical | H12: /contact | I12: URL PRESERVED as-is. Fix the form. Check shortcode renders.
A13: A | B13: /interlock-contractors-dubai/ | C13: 12 | D13: 633 | E13: 0.019 | F13: 21 | G13: Keep URL identical | H13: /services/road-works/heavy-duty-interlock-paving | I13: CORE PRODUCT. CTR 1.90% at pos 21 with RESIDENTIAL content. Keep URL, rewrite for industrial.
... A15: A | B15: /land-clearing-services-dubai/ | C15: 10 | D15: 1050 | E15: 0.0095 | F15: 22 | G15: Keep URL identical | H15: /services/earth-works/site-preparation | I15: NEW PAGE to be built. Ranks pos 5.30 for "land clearing services" with 0 clicks - rewrite title/meta.
A16: B | B16: /road-construction-dubai/ | C16: 9 | D16: 961 | E16: 0.0094 | F16: 39 | G16: Keep URL if possible, else 301 | H16: /services/road-works/dubai
A17: B | B17: /curb-stone-contractors-dubai/ | C17: 9 | D17: 817 | E17: 0.011 | F17: 11.6 | G17: Keep URL if possible, else 301 | H17: /services/road-works/kerbstones | I17: Pos 11.55. Kerbstone is part of the interlock/paving offer.
A18: B | B18: /parking-construction-dubai/ | C18: 9 | D18: 435 | E18: 0.0207 | F18: 13.9 | G18: Keep URL if possible, else 301 | H18: /services/road-works/parking-construction | I18: CORE PRODUCT. CTR 2.07%, pos 13.9. Expand to warehouse/yard paving.
A19: B | B19: /heavy-equipment-rental-uae/ | C19: 8 | D19: 2007 | E19: 0.004 | F19: 49.2 | G19: Keep URL if possible, else 301 | H19: /services | I19: 2,007 impressions at pos 49. Decide if you actually rent equipment.
A20: B | B20: /road-closure-permits/ | C20: 8 | D20: 943 | E20: 0.0085 | F20: 8.9 | G20: Keep URL if possible, else 301 | H20: /services/traffic-management/road-closure-permits
A21: B | B21: /traffic-diversions/ | C21: 8 | D21: 762 | E21: 0.0105 | F21: 8.2 | G21: Keep URL if possible, else 301 | H21: /services/traffic-management/traffic-management
A22: B | B22: /road-marking-company-dubai/ | C22: 7 | D22: 1086 | E22: 0.0064 | F22: 19.2 | G22: Keep URL if possible, else 301 | H22: /services/road-works/road-markings
A23: B | B23: /leveling-and-grading/ | C23: 7 | D23: 669 | E23: 0.0105 | F23: 22.2 | G23: Keep URL if possible, else 301 | H23: /services/earth-works/leveling-and-compaction
A24: B | B24: /piling-contractors-dubai/ | C24: 7 | D24: 456 | E24: 0.0154 | F24: 40.5 | G24: Keep URL if possible, else 301 | H24: /services/earth-works/excavation | I24: YOU DO NOT OFFER PILING. Redirect to excavation or earthworks.
A25: B | B25: /about/ | C25: 6 | D25: 656 | E25: 0.0091 | F25: 25.8 | G25: Keep URL if possible, else 301 | H25: /about | I25: URL PRESERVED as-is.
A26: B | B26: /excavation-service-abu-dhabi/ | C26: 6 | D26: 415 | E26: 0.0145 | F26: 27.1 | G26: Keep URL if possible, else 301 | H26: /services/earth-works/abu-dhabi
A27: B | B27: /construction-companies-in-uae/ | C27: 5 | D27: 1182 | E27: 0.0042 | F27: 47.1 | G27: Keep URL if possible, else 301 | H27: /about
A28: B | B28: /site-preparation/ | C28: 5 | D28: 955 | E28: 0.0052 | F28: 31.1 | G28: Keep URL if possible, else 301 | H28: /services/earth-works/site-preparation | I28: NEW PAGE to be built.
A29: B | B29: /excavation-contractors-dubai/ | C29: 5 | D29: 854 | E29: 0.0059 | F29: 30.2 | G29: Keep URL if possible, else 301 | H29: /services/earth-works/excavation
A30: B | B30: /pipeline-laying-dubai/ | C30: 5 | D30: 714 | E30: 0.007 | F30: 23.1 | G30: Keep URL if possible, else 301 | H30: /services/utilities/utilities-shifting
A31: B | B31: /infrastructure-piping-dubai/ | C31: 5 | D31: 370 | E31: 0.0135 | F31: 32.2 | G31: Keep URL if possible, else 301 | H31: /services/utilities
A32: B | B32: /piling-in-construction/ | C32: 4 | D32: 2780 | E32: 0.0014 | F32: 41 | G32: Keep URL if possible, else 301 | H32: /services/earth-works/excavation | I32: YOU DO NOT OFFER PILING. 2,780 impressions wasted. Redirect to excavation or earthworks.
A33: B | B33: /traffic-management/ | C33: 4 | D33: 1355 | E33: 0.003 | F33: 28 | G33: Keep URL if possible, else 301 | H33: /services/traffic-management
A34: B | B34: /earth-work-services-dubai/ | C34: 4 | D34: 960 | E34: 0.0042 | F34: 37.2 | G34: Keep URL if possible, else 301 | H34: /services/earth-works/dubai
A35: B | B35: /projects/ | C35: 4 | D35: 584 | E35: 0.0068 | F35: 8.4 | G35: Keep URL if possible, else 301 | H35: /projects | I35: URL PRESERVED as-is. Pos 8.38. Your portfolio hub - migrate the AED-value case studies here.
A36: B | B36: /breakwater-construction-dubai/ | C36: 4 | D36: 291 | E36: 0.0137 | F36: 17.6 | G36: Keep URL if possible, else 301 | H36: /services/earth-works
A37: B | B37: /sand-supply-dubai/ | C37: 3 | D37: 1128 | E37: 0.0027 | F37: 33.6 | G37: Keep URL if possible, else 301 | H37: /services/supply/sand-supply | I37: NEW PAGE to be built.
A38: B | B38: /temporary-road-contractors-dubai/ | C38: 3 | D38: 536 | E38: 0.0056 | F38: 24.3 | G38: Keep URL if possible, else 301 | H38: /services/road-works/access-roads
A39: B | B39: /gabion-boxes-supply-dubai/ | C39: 3 | D39: 427 | E39: 0.007 | F39: 18.3 | G39: Keep URL if possible, else 301 | H39: /services/supply/gabion-boxes | I39: NEW PAGE to be built.
A40: B | B40: /golf-course-landscaping-dubai/ | C40: 3 | D40: 133 | E40: 0.0226 | F40: 18.4 | G40: Keep URL if possible, else 301 | H40: /services/earth-works
A41: B | B41: /road-works-fujairah/ | C41: 3 | D41: 65 | E41: 0.0462 | F41: 8.4 | G41: Keep URL if possible, else 301 | H41: /services/road-works/fujairah | I41: HIGHEST CTR ON SITE (4.62%) at pos 8.45. Keep URL. Expand content.
...

Sheet Summary
A1: Tier | B1: Description | C1: URLs | D1: Clicks | E1: Impressions | F1: % of clicks
A2: A | B2: Must preserve - keep URL identical | C2: =COUNTIF('Redirect Map'!$A$2:$A$75,$A2) | D2: =SUMIF('Redirect Map'!$A$2:$A$75,$A2,'Redirect Map'!$C$2:$C$75) | E2: =SUMIF('Redirect Map'!$A$2:$A$75,$A2,'Redirect Map'!$D$2:$D$75) | F2: =IFERROR($D2/$D$6,0)
A3: B | B3: Preserve - keep or 301 to closest | C3: =COUNTIF('Redirect Map'!$A$2:$A$75,$A3) | D3: =SUMIF('Redirect Map'!$A$2:$A$75,$A3,'Redirect Map'!$C$2:$C$75) | E3: =SUMIF('Redirect Map'!$A$2:$A$75,$A3,'Redirect Map'!$D$2:$D$75) | F3: =IFERROR($D3/$D$6,0)
A4: C | B4: Redirect - 301 to closest new page | C4: =COUNTIF('Redirect Map'!$A$2:$A$75,$A4) | D4: =SUMIF('Redirect Map'!$A$2:$A$75,$A4,'Redirect Map'!$C$2:$C$75) | E4: =SUMIF('Redirect Map'!$A$2:$A$75,$A4,'Redirect Map'!$D$2:$D$75) | F4: =IFERROR($D4/$D$6,0)
A5: D | B5: Low value - 301 to parent or 404 | C5: =COUNTIF('Redirect Map'!$A$2:$A$75,$A5) | D5: =SUMIF('Redirect Map'!$A$2:$A$75,$A5,'Redirect Map'!$C$2:$C$75) | E5: =SUMIF('Redirect Map'!$A$2:$A$75,$A5,'Redirect Map'!$D$2:$D$75) | F5: =IFERROR($D5/$D$6,0)
A6: TOTAL | C6: =SUM(C2:C5) | D6: =SUM(D2:D5) | E6: =SUM(E2:E5) | F6: =IFERROR(D6/D6,0)
A8: Mapped so far | C8: =COUNTIF('Redirect Map'!$H$2:$H$75,"?*")
A9: Still to map | C9: =C6-C8
A11: Source: Google Search Console export, earthmoversint.com, 29 May - 28 Aug 2026.
A12: Tier thresholds set by Claude: A >=10 clicks; B >=3 clicks or >=800 impressions; C >=1 click or >=200 impressions; D below that.
